# АНАЛИЗ ОБРАБОТКИ ОШИБОК: family_communication_replacement.py

## ЭТАП 6.9: ПРОВЕРКА ОБРАБОТКИ ОШИБОК

### 6.9.1 - ПРОВЕРКА TRY-EXCEPT БЛОКОВ В МЕТОДАХ:

#### **ExternalAPIHandler методы:**

✅ **send_telegram_message** - строки 129-153
```python
try:
    if not self.telegram_token:
        self.logger.warning("Telegram token не настроен")
        return False
    # ... код отправки
except Exception as e:
    self.logger.error(f"Ошибка отправки Telegram сообщения: {e}")
    return False
```
- **Статус**: ✅ Присутствует
- **Тип исключения**: `Exception` (общий)
- **Обработка**: Логирование ошибки и возврат False

✅ **send_discord_message** - строки 171-201
```python
try:
    if not self.discord_token:
        self.logger.warning("Discord token не настроен")
        return False
    # ... код отправки
except Exception as e:
    self.logger.error(f"Ошибка отправки Discord сообщения: {e}")
    return False
```
- **Статус**: ✅ Присутствует
- **Тип исключения**: `Exception` (общий)
- **Обработка**: Логирование ошибки и возврат False

✅ **send_sms** - строки 216-243
```python
try:
    if not self.twilio_sid or not self.twilio_token:
        self.logger.warning("Twilio credentials не настроены")
        return False
    # ... код отправки
except Exception as e:
    self.logger.error(f"Ошибка отправки SMS: {e}")
    return False
```
- **Статус**: ✅ Присутствует
- **Тип исключения**: `Exception` (общий)
- **Обработка**: Логирование ошибки и возврат False

#### **FamilyCommunicationReplacement методы:**

✅ **__init__** - строки 274-293
```python
try:
    from security.ai_agents.smart_notification_manager import SmartNotificationManager
    self.notification_manager = SmartNotificationManager()
    self.logger.info("SmartNotificationManager успешно импортирован")
except ImportError as e:
    self.logger.error(f"Ошибка импорта SmartNotificationManager: {e}")
    self.notification_manager = None

try:
    from security.ai_agents.contextual_alert_system import ContextualAlertSystem
    self.alert_system = ContextualAlertSystem()
    self.logger.info("ContextualAlertSystem успешно импортирован")
except ImportError as e:
    self.logger.error(f"Ошибка импорта ContextualAlertSystem: {e}")
    self.alert_system = None
```
- **Статус**: ✅ Присутствует
- **Тип исключения**: `ImportError` (специфичный)
- **Обработка**: Логирование ошибки и установка None

✅ **add_family_member** - строки 307-312
```python
try:
    self.members[member.id] = member
    self.stats["active_members"] = len(self.members)
    self.logger.info(f"Добавлен член семьи: {member.name}")
    return True
except Exception as e:
    self.logger.error(f"Ошибка добавления члена семьи: {e}")
    return False
```
- **Статус**: ✅ Присутствует
- **Тип исключения**: `Exception` (общий)
- **Обработка**: Логирование ошибки и возврат False

✅ **send_message** - строки 326-416
```python
try:
    # ... код отправки сообщения
    return success_count > 0
except Exception as e:
    self.logger.error(f"Ошибка отправки сообщения: {e}")
    return False
```
- **Статус**: ✅ Присутствует
- **Тип исключения**: `Exception` (общий)
- **Обработка**: Логирование ошибки и возврат False

### 6.9.2 - ПРОВЕРКА КОРРЕКТНОСТИ ОБРАБОТКИ ИСКЛЮЧЕНИЙ:

#### **Анализ типов исключений:**
- **ImportError**: 2 блока (специфичный тип) ✅
- **Exception**: 7 блоков (общий тип) ⚠️

#### **Анализ обработки:**
- **Логирование ошибок**: ✅ Все блоки логируют ошибки
- **Возврат значений**: ✅ Все блоки возвращают подходящие значения
- **Продолжение работы**: ✅ Система продолжает работать после ошибок

### 6.9.3 - ПРОВЕРКА ЛОГИРОВАНИЯ ОШИБОК:

#### **Уровни логирования:**
- **ERROR**: 7 блоков (критические ошибки)
- **WARNING**: 3 блока (предупреждения)
- **INFO**: 2 блока (информационные сообщения)

#### **Качество сообщений об ошибках:**
- **Описательные**: ✅ Все сообщения содержат описание ошибки
- **Контекстные**: ✅ Сообщения содержат контекст операции
- **Структурированные**: ✅ Используется f-string для форматирования

### 6.9.4 - ПРОВЕРКА ВОЗВРАТА ОШИБОК В МЕТОДАХ:

#### **Анализ возвращаемых значений:**
- **bool методы**: Возвращают False при ошибке ✅
- **void методы**: Логируют ошибку и продолжают работу ✅
- **Значения по умолчанию**: Устанавливаются при ошибке импорта ✅

## СТАТИСТИКА ОБРАБОТКИ ОШИБОК:

### **По методам:**
- **Всего методов**: 11
- **С try-except**: 9 (81.8%)
- **Без try-except**: 2 (18.2%)

### **По типам исключений:**
- **ImportError**: 2 блока (18.2%)
- **Exception**: 7 блоков (63.6%)
- **Специфичные**: 0 блоков (0%)

### **По уровням логирования:**
- **ERROR**: 7 сообщений (58.3%)
- **WARNING**: 3 сообщения (25%)
- **INFO**: 2 сообщения (16.7%)

## РЕКОМЕНДАЦИИ ПО УЛУЧШЕНИЮ:

### 🔧 ПРЕДЛАГАЕМЫЕ УЛУЧШЕНИЯ:

#### **1. Добавить специфичные типы исключений:**

```python
async def send_telegram_message(self, chat_id: str, text: str, parse_mode: str = "HTML") -> bool:
    try:
        if not self.telegram_token:
            self.logger.warning("Telegram token не настроен")
            return False
        
        url = f"https://api.telegram.org/bot{self.telegram_token}/sendMessage"
        data = {"chat_id": chat_id, "text": text, "parse_mode": parse_mode}
        
        async with aiohttp.ClientSession() as session:
            async with session.post(url, json=data) as response:
                if response.status == 200:
                    self.logger.info(f"Telegram сообщение отправлено в {chat_id}")
                    return True
                else:
                    self.logger.error(f"Ошибка отправки Telegram: {response.status}")
                    return False
                    
    except aiohttp.ClientError as e:
        self.logger.error(f"Ошибка сети при отправке Telegram: {e}")
        return False
    except ValueError as e:
        self.logger.error(f"Некорректные данные для Telegram: {e}")
        return False
    except Exception as e:
        self.logger.error(f"Неожиданная ошибка при отправке Telegram: {e}")
        return False
```

#### **2. Добавить валидацию входных данных:**

```python
async def add_family_member(self, member: FamilyMember) -> bool:
    try:
        # Валидация входных данных
        if not member or not member.id:
            raise ValueError("Член семьи не может быть пустым")
        if not member.name:
            raise ValueError("Имя члена семьи не может быть пустым")
        if member.id in self.members:
            raise ValueError(f"Член семьи с ID {member.id} уже существует")
        
        self.members[member.id] = member
        self.stats["active_members"] = len(self.members)
        self.logger.info(f"Добавлен член семьи: {member.name}")
        return True
        
    except ValueError as e:
        self.logger.error(f"Ошибка валидации: {e}")
        return False
    except Exception as e:
        self.logger.error(f"Ошибка добавления члена семьи: {e}")
        return False
```

#### **3. Добавить retry механизм:**

```python
import asyncio
from typing import Optional

async def send_message_with_retry(self, message: Message, max_retries: int = 3) -> bool:
    """Отправка сообщения с повторными попытками"""
    for attempt in range(max_retries):
        try:
            return await self.send_message(message)
        except Exception as e:
            if attempt == max_retries - 1:
                self.logger.error(f"Ошибка отправки после {max_retries} попыток: {e}")
                return False
            else:
                self.logger.warning(f"Попытка {attempt + 1} не удалась: {e}")
                await asyncio.sleep(2 ** attempt)  # Экспоненциальная задержка
    return False
```

#### **4. Добавить метрики ошибок:**

```python
class FamilyCommunicationReplacement:
    def __init__(self, family_id: str, config: Dict[str, Any]) -> None:
        # ... существующий код
        self.error_stats = {
            "total_errors": 0,
            "error_types": {},
            "last_error": None,
            "error_rate": 0.0
        }
    
    def _log_error(self, error_type: str, error: Exception) -> None:
        """Логирование ошибки с метриками"""
        self.error_stats["total_errors"] += 1
        self.error_stats["error_types"][error_type] = self.error_stats["error_types"].get(error_type, 0) + 1
        self.error_stats["last_error"] = str(error)
        
        # Обновление error_rate
        total_operations = self.stats["total_messages"] + self.error_stats["total_errors"]
        if total_operations > 0:
            self.error_stats["error_rate"] = self.error_stats["total_errors"] / total_operations
        
        self.logger.error(f"[{error_type}] {error}")
```

#### **5. Добавить контекстный менеджер для обработки ошибок:**

```python
from contextlib import asynccontextmanager

@asynccontextmanager
async def error_context(self, operation_name: str):
    """Контекстный менеджер для обработки ошибок"""
    try:
        yield
    except Exception as e:
        self._log_error(operation_name, e)
        raise

# Использование:
async def send_message(self, message: Message) -> bool:
    async with self.error_context("send_message"):
        # ... код отправки сообщения
        return success_count > 0
```

## ПРИОРИТЕТЫ УЛУЧШЕНИЯ:

### **Высокий приоритет:**
1. **Добавить специфичные типы исключений** (aiohttp.ClientError, ValueError)
2. **Добавить валидацию входных данных** в критических методах
3. **Улучшить сообщения об ошибках** с более подробной информацией

### **Средний приоритет:**
4. **Добавить retry механизм** для сетевых операций
5. **Добавить метрики ошибок** для мониторинга
6. **Добавить контекстный менеджер** для обработки ошибок

### **Низкий приоритет:**
7. **Добавить уведомления об ошибках** администраторам
8. **Добавить автоматическое восстановление** после ошибок
9. **Добавить детальное логирование** для отладки

## ЗАКЛЮЧЕНИЕ:

Обработка ошибок присутствует в большинстве методов (81.8%) и в целом корректна. Все ошибки логируются и обрабатываются должным образом. Рекомендуется добавить специфичные типы исключений и валидацию входных данных для улучшения качества обработки ошибок.